Workbook

Sheet COVER
B2: HEAT EXCHANGER TUBE THICKNESS CALCULATOR
B3: Per ASME Sec VIII Div 1 | TEMA | API 660 | IOGP S-614
B5: Standards Referenced | C5: Clause / Scope
B6: ASME Section VIII Div 1 | C6: UG-27, UG-28, UG-31 — Pressure vessel tube thickness
B7: TEMA 10th Edition | C7: RGP-T-2.4 — Minimum tube wall thickness
B8: API 660 9th Edition | C8: Shell-and-tube HE requirements, tube sizing table
B9: IOGP S-614 | C9: Supplementary spec to API 660 for shell-and-tube HEs
B11: Color Legend | C11: Meaning
B12: Yellow / Blue text | C12: USER INPUT — cells to fill in
B13: Light blue | C13: Calculated value (do not edit)
B14: Green | C14: PASS — requirement satisfied
B15: Light red | C15: FAIL — requirement NOT met
B16: Orange | C16: Warning / requires attention
B18: Instructions
B19: 1. Go to INPUTS sheet → fill all yellow cells with your project data.
B20: 2. In MATERIALS sheet, verify or update allowable stress for your material & temperature.
B21: 3. ASME_VIII sheet auto-calculates required thickness per UG-27 / UG-28 / UG-31.
B22: 4. TEMA sheet checks minimum wall per TEMA RGP-T-2.4 table.
B23: 5. API_660 sheet checks minimum wall per API 660 Table 5.
B24: 6. IOGP sheet lists IOGP S-614 supplementary considerations (verify vs actual document).
B25: 7. SUMMARY sheet shows governing (largest) required thickness and final PASS/FAIL.
B27: Created: 2026-10-21

Sheet INPUTS
B1: DESIGN INPUTS — Fill all yellow cells
B3: PROJECT INFORMATION
B4: Project Name | D4: Project XYZ
B5: Equipment Tag No. | D5: HE-101
B6: Document No. | D6: CALC-HE-101-001
B7: Revision | D7: 0
B8: Prepared By | D8: Engineer Name
B9: Date | D9: 2026-10-21
B11: TUBE GEOMETRY
B12: Parameter | D12: Value | E12: Unit
B13: Tube Outside Diameter (OD) | C13: D_o | D13: 19.05 | E13: mm | F13: Typical: 15.88, 19.05, 25.4, 31.75, 38.1, 50.8 mm
B14: Nominal Wall Thickness (trial) | C14: t_nom | D14: 2.11 | E14: mm | F14: Initial trial; verified by calculation
B15: Tube Inside Diameter (ID) | C15: D_i | D15: =D13-2*D14 -> 14.83 | E15: mm | F15: Calculated
B16: Cross-Section Flow Area | C16: A_i | D16: =PI()/4*(D15^2)/1000000 -> 0.00017273175 | E16: m² | F16: Calculated
B17: Tube Length (effective) | C17: L_eff | D17: 4880 | E17: mm | F17: Face-to-face tube length
B18: Unsupported Tube Span | C18: L_us | D18: 1220 | E18: mm | F18: Max span between baffles/supports (TEMA RGP-T-4.1)
B20: DESIGN CONDITIONS
B21: Parameter | C21: Symbol | D21: Value | E21: Unit
B22: Design Internal Pressure (gauge) | C22: P_i | D22: 40 | E22: barg | F22: ASME UG-27 internal pressure
B23: Design External Pressure (gauge) | C23: P_e | D23: 0.1 | E23: barg | F23: 0.1 barg = full vacuum + 0 barg
B24: Design Temperature | C24: T_d | D24: 200 | E24: °C | F24: Metal temperature at design condition
B25: Operating Internal Pressure | C25: P_op | D25: 38 | E25: barg | F25: For reference only
B26: Operating Temperature | C26: T_op | D26: 185 | E26: °C | F26: For reference only
B28: MATERIAL PROPERTIES
B29: Parameter | C29: Symbol | D29: Value | E29: Unit
B30: Tube Material / Grade | C30: Mat. | D30: SA-179 / SMLS CS | E30: — | F30: ASME IID Table 1A
B31: Allowable Stress at Design T | C31: S | D31: 92.6 | E31: MPa | F31: SA-179 example; see MATERIALS. VERIFY vs ASME II-D
B32: Young's Modulus at Design T | C32: E_m | D32: 193 | E32: GPa | F32: From ASME IID Table TM-1
B33: Poisson's Ratio | C33: ν | D33: 0.3 | E33: — | F33: Typical for steel
B35: FABRICATION ALLOWANCES
B36: Parameter | C36: Symbol | D36: Value | E36: Unit
B37: Corrosion Allowance (tube-side) | C37: CA_i | D37: 0.5 | E37: mm | F37: Inside corrosion; 0 if non-corrosive / CRA lined
B38: Corrosion Allowance (shell-side) | C38: CA_o | D38: 0.5 | E38: mm | F38: Outside corrosion; 0 if non-corrosive
B39: Mill Tolerance | C39: MT | D39: 12.5 | E39: % | F39: ASTM A179/A213 allow -12.5% on wall
B40: Joint Efficiency | C40: E | D40: 1 | E40: — | F40: 1.0 = seamless tube; 0.85 = ERW; per UW-12
B41: Weld Examination Factor | C41: W_f | D41: 1 | E41: — | F41: 1.0 for seamless; per UW-12 for welded
B43: HEAT EXCHANGER BUNDLE GEOMETRY
B44: Parameter | C44: Symbol | D44: Value | E44: Unit
B45: Number of Tubes | C45: N_t | D45: 400 | E45: — | F45: Total number of tubes in bundle
B46: Number of Tube Passes | C46: N_p | D46: 2 | E46: — | F46: TEMA Type: 1=E, 2=E2, 4=E4, etc.
...

Sheet MATERIALS
B1: MATERIALS — Allowable Stress (MPa) — Source: ASME Section IID Table 1A / 1B
B2: Allowable stress S computed as min(UTS/3.5, 2*Yield/3) per ASME VIII-1 basis, room temp. INDICATIVE ONLY - verify EVERY value against ASME BPVC II-D Table 1A/1B for the controlling edition & temperature before design use.
B3: Material | C3: Spec / Grade | D3: Min UTS (MPa) | E3: 20°C | F3: 50°C | G3: 100°C | H3: 150°C | I3: 200°C | J3: 250°C | K3: 300°C | L3: 350°C | M3: Notes
B4: Carbon Steel (CS) | C4: SA-179 SMLS | D4: 325 | E4: 92.6 | F4: 92.6 | G4: 92.6 | H4: 92.6 | I4: 92.6 | J4: 92.6 | K4: 92.6 | L4: 92.6 | M4: S=UTS/3.5 (UTS 47ksi); flat <=340C
B5: Carbon Steel (CS) | C5: SA-192 SMLS | D5: 325 | E5: 92.6 | F5: 92.6 | G5: 92.6 | H5: 92.6 | I5: 92.6 | J5: 92.6 | K5: 92.6 | L5: 92.6 | M5: S=UTS/3.5 (UTS 47ksi); flat <=340C
B6: C-Mo Steel | C6: SA-209 T1 | D6: 380 | E6: 108.6 | F6: 108.6 | G6: 108.6 | H6: 108.6 | I6: 108.6 | J6: 108.6 | K6: 108.6 | L6: 105 | M6: S=UTS/3.5 (UTS 55ksi); creep >450C
B7: 1-1/4Cr-1/2Mo | C7: SA-213 T11 | D7: 415 | E7: 118.6 | F7: 118.6 | G7: 118.6 | H7: 118.6 | I7: 118.6 | J7: 118.6 | K7: 118.6 | L7: 118.6 | M7: S=UTS/3.5 (UTS 60ksi); creep >480C
B8: 2-1/4Cr-1Mo | C8: SA-213 T22 | D8: 415 | E8: 118.6 | F8: 118.6 | G8: 118.6 | H8: 118.6 | I8: 118.6 | J8: 118.6 | K8: 118.6 | L8: 118.6 | M8: S=UTS/3.5 (UTS 60ksi); creep >480C
B9: 5Cr-0.5Mo | C9: SA-213 T5 | D9: 415 | E9: 118.6 | F9: 118.6 | G9: 118.6 | H9: 118.6 | I9: 118.6 | J9: 118.6 | K9: 118.6 | L9: 118.6 | M9: S=UTS/3.5 (UTS 60ksi)
B10: 9Cr-1Mo (P91) | C10: SA-213 T91 | D10: 585 | E10: 167.1 | F10: 167.1 | G10: 167.1 | H10: 167.1 | I10: 167.1 | J10: 167.1 | K10: 167.1 | L10: 167.1 | M10: S=UTS/3.5 (UTS 85ksi)
B11: 304 SS | C11: SA-213 TP304 | D11: 515 | E11: 137.9 | F11: 137.9 | G11: 137.9 | H11: 131.7 | I11: 122 | J11: 116.5 | K11: 110.3 | L11: 104.8 | M11: Austenitic SS
B12: 316 SS | C12: SA-213 TP316 | D12: 515 | E12: 137.9 | F12: 137.9 | G12: 137.9 | H12: 131.7 | I12: 125.5 | J12: 119.3 | K12: 113 | L12: 108.3 | M12: Austenitic SS Mo-bearing
B13: 321 SS | C13: SA-213 TP321 | D13: 515 | E13: 137.9 | F13: 137.9 | G13: 137.9 | H13: 131.7 | I13: 122 | J13: 116.5 | K13: 110.3 | L13: 104.8 | M13: Ti-stabilized SS
B14: 347 SS | C14: SA-213 TP347 | D14: 515 | E14: 137.9 | F14: 137.9 | G14: 137.9 | H14: 131.7 | I14: 122 | J14: 116.5 | K14: 110.3 | L14: 104.8 | M14: Nb-stabilized SS
B15: Duplex 2205 | C15: SA-789 S31803 | D15: 620 | E15: 172.4 | F15: 172.4 | G15: 172.4 | H15: 172.4 | I15: 165.5 | J15: 155.2 | K15: 144.8 | L15: — | M15: Duplex SS, max 300°C
B16: Super Duplex 2507 | C16: SA-789 S32750 | D16: 795 | E16: 206.8 | F16: 206.8 | G16: 206.8 | H16: 196.5 | I16: 186.2 | J16: 176 | K16: 165.5 | L16: — | M16: Super Duplex SS
B17: Alloy 825 (Incoloy) | C17: SB-163 N08825 | D17: 586 | E17: 131 | F17: 131 | G17: 131 | H17: 131 | I17: 131 | J17: 131 | K17: 131 | L17: 124 | M17: Ni-Fe-Cr-Mo alloy
B18: Alloy 625 (Inconel) | C18: SB-444 N06625 | D18: 827 | E18: 206.8 | F18: 206.8 | G18: 206.8 | H18: 206.8 | I18: 206.8 | J18: 206.8 | K18: 206.8 | L18: 206.8 | M18: Ni-Cr-Mo alloy
B19: Copper-Nickel 90/10 | C19: SB-111 C70600 | D19: 275 | E19: 62.1 | F19: 58.6 | G19: 55.2 | H19: 52.4 | I19: 48.3 | J19: — | K19: — | L19: — | M19: Cu-Ni, max 232°C
B20: Copper-Nickel 70/30 | C20: SB-111 C71500 | D20: 345 | E20: 75.8 | F20: 72.4 | G20: 69 | H20: 65.5 | I20: 60.7 | J20: — | K20: — | L20: — | M20: Cu-Ni, max 260°C
B21: Admiralty Brass | C21: SB-111 C44300 | D21: 370 | E21: 82.7 | F21: 80 | G21: 75.8 | H21: — | I21: — | J21: — | K21: — | L21: — | M21: Max 150°C
B22: Titanium Gr 2 | C22: SB-338 R50400 | D22: 345 | E22: 75.8 | F22: 75.8 | G22: 68.9 | H22: 62 | I22: 55.2 | J22: — | K22: — | L22: — | M22: Ti alloy, max 260°C
B24: NOTE: Values shown are indicative per ASME IID (2021). Always verify against the applicable code edition and specific heat-treatment condition. Highlighted cells = material not rated at that temperature.

Sheet ASME_VIII
B1: ASME SECTION VIII DIV 1 — TUBE THICKNESS CALCULATION
B2: Reference: UG-27(c), UG-28, UG-31, Appendix 1-1
B4: Parameter | C4: Symbol | D4: Value | E4: Unit
B5: Tube Outside Diameter | C5: D_o | D5: =INPUTS!D13 -> 19.05 | E5: mm
B6: Nominal Wall Thickness | C6: t_nom | D6: =INPUTS!D14 -> 2.11 | E6: mm
B7: Design Internal Pressure (barg→MPa) | C7: P_i | D7: =INPUTS!D22*0.1 -> 4 | E7: MPa
B8: Design External Pressure (barg→MPa) | C8: P_e | D8: =INPUTS!D23*0.1 -> 0.01 | E8: MPa
B9: Allowable Stress at Design Temp | C9: S | D9: =INPUTS!D31 -> 92.6 | E9: MPa
B10: Joint Efficiency | C10: E | D10: =INPUTS!D40 -> 1 | E10: —
B11: Corrosion Allowance (total = CA_i+CA_o) | C11: CA | D11: =INPUTS!D37+INPUTS!D38 -> 1 | E11: mm
B12: Mill Tolerance | C12: MT | D12: =INPUTS!D39/100 -> 0.125 | E12: fraction
B13: Young's Modulus | C13: E_mod | D13: =INPUTS!D32*1000 -> 193000 | E13: MPa
B14: Poisson's Ratio | C14: ν | D14: =INPUTS!D33 -> 0.3 | E14: —
B15: Unsupported Tube Span | C15: L_us | D15: =INPUTS!D18 -> 1220 | E15: mm
B17: Calculation Step | C17: Symbol | D17: Result | E17: Unit
B18: t_req = P_i·D_o / (2·(S·E + 0.4·P_i)) | C18: t_req | D18: =D7*D5/(2*(D9*D10+0.4*D7)) -> 0.4044586 | E18: mm | F18: Eq UG-27(c)(1) rearranged to use OD; = t using ID form where R = D_i/2
B19: Minimum nominal thickness = (t_req + CA) / (1 – MT) | C19: t_nom_min | D19: =(D18+D11)/(1-D12) -> 1.6050955 | E19: mm | F19: Required nominal thickness ordered; add CA then divide by mill factor
B20: Net available thickness = t_nom·(1–MT) – CA | C20: t_avail | D20: =D6*(1-D12)-D11 -> 0.84625 | E20: mm | F20: Minimum actual thickness after mill tolerance and full corrosion allowance consumed
B21: MAWP = 2·S·E·t_avail / (D_o – 0.8·t_avail) | C21: MAWP | D21: =2*D9*D10*D20/(D5-0.8*D20) -> 8.5302074 | E21: MPa | F21: Maximum Allowable Working Pressure on nominal corroded wall
B22: MAWP (barg) | C22: MAWP_b | D22: =D21/0.1 -> 85.302074 | E22: barg
B23: INTERNAL PRESSURE CHECK: t_avail ≥ t_req ? | D23: =IF(D20>=D18,"PASS","FAIL") -> PASS
B25: Calculation Step | C25: Symbol | D25: Result | E25: Unit
B26: Do / t_avail ratio | C26: Do_t | D26: =D5/D20 -> 22.511078 | E26: — | F26: If Do/t < 10 → thick cylinder, use different formula
B27: L_us / Do ratio | C27: L_D | D27: =D15/D5 -> 64.041995 | E27: — | F27: Slenderness ratio for external pressure chart
B28: Geometric Factor A (ASME Fig G approx.) | C28: A | D28: =0.125/(D27/D26) -> 0.043938119 | E28: — | F28: Approximation: A ≈ 0.125 / (L/Do / (Do/t)); rigorous: read ASME Sect II Part D Figure G
B29: Factor B = 0.9·E_mod·(t/Do)·A (elastic range) | C29: B | D29: =0.9*D13*(D20/D5)*D28 -> 339.03535 | E29: MPa | F29: If B ≤ S/2, elastic buckling governs
B30: Allowable ext. pressure P_a = B / (3·(Do/t)/4) [UG-28 elastic] | C30: P_a_e | D30: =D29/(0.75*D26) -> 20.081096 | E30: MPa | F30: Elastic buckling allowable; see Appendix 1-2
B31: Allowable ext. pressure P_a = S·t_avail / (0.5·Do) [plastic limit] | C31: P_a_p | D31: =D9*D20/(0.5*D5) -> 8.2270604 | E31: MPa | F31: Plastic / yield-based limit (conservative upper)
B32: Governing P_a = MIN(elastic, plastic) | C32: P_a | D32: =MIN(D30,D31) -> 8.2270604 | E32: MPa | F32: Use the lesser value per ASME intent
B33: EXTERNAL PRESSURE CHECK: P_a ≥ P_e ? | D33: =IF(D32>=D8,"PASS","FAIL") -> PASS | E33: =_xlfn.CONCAT("P_a=",TEXT(D32,"0.000")," MPa vs P_e=",TEXT(D8,"0.000")," MPa") -> P_a=8.227 MPa vs P_e=0.010 MPa
B35: ⚠ NOTE: External pressure calculation here uses an analytical approximation of ASME Figure G. For final design, the rigorous chart-based method per ASME VIII Div 1 UG-28 and Figure G + material charts (Section II Part D) MUST be followed. The approximation above is conservative for preliminary sizing only.
B37: Calculation Step | C37: Symbol | D37: Result | E37: Unit
B38: t_long = P_i·D_o / (4·S·E − 0.8·P_i) [Appendix 1-1(a)(2)] | C38: t_long | D38: =D7*D5/(4*D9*D10-0.8*D7) -> 0.20751634 | E38: mm | F38: Longitudinal stress (circ. joints); ~half of circumferential, rarely governs
B39: Governing ASME thickness (max of int. and long.) | C39: t_gov_asme | D39: =MAX(D18,D38) -> 0.4044586 | E39: mm | F39: Governs for thickness ordering (before CA & MT)
B42: FORMULA VALIDATION — against published UG-27 worked example
B43: Validation Step | C43: Symbol | D43: Result | E43: Unit
B44: Example inputs (Kezar Eng.): P=1.60 MPa, R_i=1000 mm, S=138 MPa, E=0.85 | C44: — | D44: — | E44: — | F44: Published circumferential answer = 13.75 mm
B45: ID form t = P·R/(S·E − 0.6·P) | C45: t_ID | D45: =1.6*1000/(138*0.85-0.6*1.6) -> 13.752794 | E45: mm | F45: Should reproduce 13.75 mm → validates ID formula
B46: OD form (this sheet's method), D_o = 2020 mm | C46: t_OD | D46: =1.6*2020/(2*(138*0.85+0.4*1.6)) -> 13.701882 | E46: mm | F46: Same case via OD form used by this workbook (~13.70 mm)
B47: Agreement within ID/OD rounding (<0.5%)? | C47: check | D47: =IF(ABS(D45-D46)/D45<0.01,"VALIDATED","REVIEW") -> VALIDATED | E47: — | F47: Confirms the sheet's OD formula matches the published result

Sheet TEMA
B1: TEMA — MINIMUM TUBE WALL (gauge) GUIDANCE
B2: Commonly specified minimum tube gauges (industry practice). VERIFY against TEMA tube tables (Table D-7 / RCB-2.4) for your class R / C / B.
B4: Common Minimum Tube Gauge vs Tube OD (nominal/ordered wall)
B5: Tube OD (in) | C5: Tube OD (mm) | D5: Min BWG | E5: Min Wall (mm) | F5: Notes
B6: 0.5 | C6: 12.7 | D6: 18 | E6: 1.245 | F6: Min per TEMA for cleanable; non-ferrous may differ
B7: 0.625 | C7: 15.875 | D7: 18 | E7: 1.245 | F7: Min per TEMA for cleanable
B8: 0.75 | C8: 19.05 | D8: 16 | E8: 1.651 | F8: Most common HX tube size
B9: 0.875 | C9: 22.225 | D9: 16 | E9: 1.651 | F9: TEMA RGP-T-2.4
B10: 1 | C10: 25.4 | D10: 14 | E10: 2.108 | F10: Standard tube for process HEs
B11: 1.25 | C11: 31.75 | D11: 14 | E11: 2.108 | F11: TEMA TEMA RGP-T-2.4
B12: 1.5 | C12: 38.1 | D12: 12 | E12: 2.769 | F12: TEMA RGP-T-2.4
B13: 2 | C13: 50.8 | D13: 12 | E13: 2.769 | F13: TEMA RGP-T-2.4
B14: 2.5 | C14: 63.5 | D14: 10 | E14: 3.404 | F14: TEMA RGP-T-2.4
B15: 3 | C15: 76.2 | D15: 10 | E15: 3.404 | F15: TEMA RGP-T-2.4
B18: TEMA COMPLIANCE CHECK
B19: Parameter | C19: Symbol | D19: Value | E19: Unit
B20: Tube OD (from INPUTS) | C20: D_o | D20: =INPUTS!D13 -> 19.05 | E20: mm
B21: Nominal wall thickness (from INPUTS) | C21: t_nom | D21: =INPUTS!D14 -> 2.11 | E21: mm
B22: TEMA minimum wall for this OD (VLOOKUP) | C22: t_TEMA | D22: =IFERROR(INDEX(E6:E15,MATCH(D20,C6:C15,0)),"OD not in TEMA table") -> 1.651 | E22: mm
B23: Minimum available net wall = t_nom×(1–MT) | C23: t_min_avail | D23: =INPUTS!D14*(1-INPUTS!D39/100) -> 1.84625 | E23: mm
B24: GAUGE CHECK: ordered wall t_nom ≥ min gauge? (net-wall adequacy is covered by ASME_VIII) | D24: =IF(ISNUMBER(D22),IF(D21>=D22,"PASS","FAIL"),"N/A - check OD") -> PASS
B26: BWG REFERENCE TABLE (Wall Thickness in mm)
B27: BWG No. | C27: Wall (mm) | D27: BWG No. | E27: Wall (mm) | F27: BWG No. | G27: Wall (mm)
B28: 7 | C28: 4.572 | D28: 8 | E28: 4.191 | F28: 9 | G28: 3.759
B29: 10 | C29: 3.404 | D29: 11 | E29: 3.048 | F29: 12 | G29: 2.769
B30: 13 | C30: 2.413 | D30: 14 | E30: 2.108 | F30: 15 | G30: 1.829
B31: 16 | C31: 1.651 | D31: 17 | E31: 1.473 | F31: 18 | G31: 1.245
B32: 19 | C32: 1.067 | D32: 20 | E32: 0.889 | F32: 22 | G32: 0.711

Sheet API_660
B1: API 660 9th EDITION (2015) — TUBE THICKNESS REQUIREMENTS
B2: Reference: API 660 Table 1 'Minimum Thickness of Tubes'. It is a minimum ORDERED (nominal) wall floor BY MATERIAL CLASS — it does NOT vary with tube OD.
B4: API 660 TABLE 1: Minimum Thickness of Tubes (by material class)
B5: Material Class | C5: Min Wall (mm) | D5: Min Wall (in) | E5: ≈ BWG | F5: Notes
B6: Carbon steel, low-alloy steel (<=9% Cr), aluminium & Al alloys | C6: 2.11 | D6: 0.083 | E6: 14 BWG | F6: Most common class
B7: Copper alloys & high-alloy (stainless) steels | C7: 1.47 | D7: 0.058 | E7: ~17 BWG | F7: 8th Ed: Cu alloys = 1.65 mm (0.065")
B8: Titanium & titanium alloys | C8: 1.07 | D8: 0.042 | E8: ~19 BWG | F8: Thinnest permitted class
B10: Table 1 is a FLOOR only: tube wall shall be the greater of this value, the ASME VIII pressure-design thickness, and any purchaser-specified corrosion/bend-thinning allowance.
B16: Topic | C16: Requirement | D16: Complied? | E16: Notes
B17: Tubes | C17: Tubes shall be seamless unless welded tube is specified / agreed | E17: Yes / To be confirmed
B18: Thickness | C18: Wall >= API 660 Table 1 min AND >= ASME VIII pressure-design thickness | E18: Yes / To be confirmed
B19: Corrosion | C19: Add any purchaser-specified tube corrosion allowance on top of Table 1 floor | E19: Yes / To be confirmed
B20: U-bends | C20: U-bend wall after thinning >= pressure-code min + corrosion allowance | E20: Yes / To be confirmed
B21: Mill tol. | C21: Account for wall undertolerance (e.g. 12.5% for many ASTM tube specs) | E21: Yes / To be confirmed
B22: Sour svc. | C22: H2S service: tubes per NACE MR0175 / ISO 15156 | E22: Yes / To be confirmed
B23: Joints | C23: Tube-to-tubesheet joint (expanded / strength-welded) per service & TEMA class | E23: Yes / To be confirmed
B24: Testing | C24: Hydrostatic / NDE per ASME VIII and TEMA class as specified | E24: Yes / To be confirmed
B27: API 660 WALL THICKNESS COMPLIANCE CHECK
B28: Parameter | C28: Symbol | D28: Value | E28: Unit
B29: Tube OD (from INPUTS) | C29: D_o | D29: =INPUTS!D13 -> 19.05 | E29: mm
B30: Nominal (ordered) wall (from INPUTS) | C30: t_nom | D30: =INPUTS!D14 -> 2.11 | E30: mm
B31: Tube material (from INPUTS) | C31: Mat. | D31: =INPUTS!D30 -> SA-179 / SMLS CS | E31: —
B32: API 660 min — CS/low-alloy/Al class | C32: t_API_1 | D32: =C6 -> 2.11 | E32: mm
B33: API 660 min — Cu-alloy/stainless class | C33: t_API_2 | D33: =C7 -> 1.47 | E33: mm
B34: API 660 min — Titanium class | C34: t_API_3 | D34: =C8 -> 1.07 | E34: mm
B35: API 660 CHECK (CS/low-alloy class): ordered wall t_nom ≥ 2.11 mm (Table 1)? | D35: =IF(D30>=D32,"PASS","FAIL") -> PASS | E35: For Cu/stainless use row 33 (1.47); for Ti use row 34 (1.07)

Sheet IOGP
B1: IOGP S-614 — SUPPLEMENTARY SPEC TO API 660 (SHELL & TUBE HEAT EXCHANGERS)
B2: IOGP S-614 supplements API 660. It requires the minimum tube wall and bend-thinning allowance to be STATED IN THE PURCHASE DOCUMENTS. Items below are TYPICAL considerations - verify against the actual S-614 text & project data sheet.
B4: IOGP S-614 / PROJECT TUBE CONSIDERATIONS (paraphrased)
B5: Topic | C5: Requirement | D5: Status | E5: Notes
B6: Tube wall | C6: Minimum required tube wall thickness shall be stated in the purchase documents (S-614) | E6: Yes / N/A
B7: Bend thinning | C7: Bend-thinning allowance for U-tubes, when applicable, stated in purchase documents | E7: Yes / N/A
B8: Base codes | C8: Supplements API 660 - API 660 Table 1 floor AND ASME VIII pressure design still apply | E8: Yes / N/A
B9: Seamless | C9: Seamless tubes generally required for pressure service unless agreed otherwise | E9: Yes / N/A
B10: Sour service | C10: H2S service: tubes per NACE MR0175 / ISO 15156 | E10: Yes / N/A
B11: NDE | C11: Supplementary NDE (e.g. 100% eddy-current) per project specification | E11: Yes / N/A
B12: Material certs | C12: Mill / material test certificates per EN 10204 3.1/3.2 or ASME as specified | E12: Yes / N/A
B13: Data sheet | C13: All project-specific tube requirements captured on the API 660 / IOGP data sheet | E13: Yes / N/A
B20: IOGP MINIMUM WALL THICKNESS CHECK
B21: Parameter | C21: Symbol | D21: Value | E21: Unit
B22: Tube OD (from INPUTS) | C22: D_o | D22: =INPUTS!D13 -> 19.05 | E22: mm
B23: Nominal (ordered) wall (from INPUTS) | C23: t_nom | D23: =INPUTS!D14 -> 2.11 | E23: mm
B24: API 660 Table 1 floor (CS/low-alloy class) | C24: t_API | D24: =API_660!C6 -> 2.11 | E24: mm
B25: Project-specified min wall (purchase doc) <-- EDIT | C25: t_spec | D25: 2.108 | E25: mm
B26: Governing IOGP min = MAX(API floor, project) | C26: t_gov | D26: =MAX(D24,D25) -> 2.11 | E26: mm
B27: IOGP CHECK: ordered wall t_nom ≥ governing min (API floor + project spec)? | D27: =IF(D23>=D26,"PASS","FAIL") -> PASS | E27: Yellow cell D25 = project value from purchase docs

Sheet SUMMARY
B1: TUBE THICKNESS CALCULATION SUMMARY
B3: TUBE DESIGN SUMMARY — KEY PARAMETERS
B4: Parameter | C4: Symbol | D4: Value | E4: Unit | F4: Source
B5: Tube Outside Diameter | C5: D_o | D5: =INPUTS!D13 -> 19.05 | E5: mm | F5: INPUTS
B6: Nominal Wall Thickness (proposed) | C6: t_nom | D6: =INPUTS!D14 -> 2.11 | E6: mm | F6: INPUTS
B7: Design Internal Pressure | C7: P_i | D7: =INPUTS!D22 -> 40 | E7: barg | F7: INPUTS
B8: Design Temperature | C8: T_d | D8: =INPUTS!D24 -> 200 | E8: °C | F8: INPUTS
B9: Allowable Stress | C9: S | D9: =INPUTS!D31 -> 92.6 | E9: MPa | F9: INPUTS / ASME IID
B10: Corrosion Allowance (total) | C10: CA | D10: =INPUTS!D37+INPUTS!D38 -> 1 | E10: mm | F10: INPUTS
B11: Mill Tolerance | C11: MT | D11: =INPUTS!D39 -> 12.5 | E11: % | F11: INPUTS
B13: MINIMUM REQUIRED THICKNESS BY STANDARD
B14: Standard / Requirement | C14: Ref. | D14: Req. Thickness (mm) | E14: Status | F14: Governs?
B15: ASME VIII UG-27 Internal Pressure (t_req) | C15: UG-27 | D15: =ASME_VIII!D18 -> 0.4044586 | E15: =IF(ASME_VIII!D23="PASS","PASS","FAIL") -> PASS
B16: ASME VIII UG-27 Longitudinal (t_long) | C16: UG-27c2 | D16: =ASME_VIII!D38 -> 0.20751634 | E16: =IF(ASME_VIII!D38<=ASME_VIII!D18,"N/A (Circ governs)","Check") -> N/A (Circ governs)
B17: ASME VIII Min nominal = (t_req+CA)/(1–MT) | C17: UG-31 | D17: =ASME_VIII!D19 -> 1.6050955 | E17: =IF(INPUTS!D14>=ASME_VIII!D19,"PASS","FAIL") -> PASS
B18: TEMA min tube gauge (common practice) | C18: TEMA | D18: =TEMA!D22 -> 1.651 | E18: =TEMA!D24 -> PASS
B19: API 660 Table 1 min (CS/low-alloy class) | C19: API660 T1 | D19: =API_660!D32 -> 2.11 | E19: =API_660!D35 -> PASS
B20: IOGP S-614 governing min wall | C20: S-614 | D20: =IOGP!D26 -> 2.11 | E20: =IOGP!D27 -> PASS
B21: GOVERNING REQUIRED THICKNESS (MAX of all standards) | D21: =_xlfn.MAXIFS(D15:D20,D15:D20,">0") -> 2.11 | E21: mm (governing)
B22: PROPOSED NOMINAL WALL THICKNESS | D22: =INPUTS!D14 -> 2.11 | E22: mm (nominal)
B23: OVERALL RESULT: Proposed t_nom ≥ Governing required thickness? | D23: =IF(INPUTS!D14>=_xlfn.MAXIFS(D15:D20,D15:D20,">0"),"PASS","FAIL — increase wall") -> PASS
B25: MAWP / PRESSURE RATINGS
B26: MAWP (internal pressure, corroded) | D26: =ASME_VIII!D21 -> 8.5302074 | E26: MPa
B27: MAWP (barg) | D27: =ASME_VIII!D22 -> 85.302074 | E27: barg
B28: External pressure allowable P_a | D28: =ASME_VIII!D32 -> 8.2270604 | E28: MPa
B30: TUBE BUNDLE SUMMARY
B31: Number of Tubes | C31: N_t | D31: =INPUTS!D45 -> 400 | E31: —
B32: Tube OD × Wall | C32: OD×t | D32: =_xlfn.CONCAT(TEXT(INPUTS!D13,"0.0"),"×",TEXT(INPUTS!D14,"0.00")) -> 19.1×2.11 | E32: mm
B33: Tube Pitch | C33: p_t | D33: =INPUTS!D47 -> 25.4 | E33: mm
B34: Tube Length | C34: L | D34: =INPUTS!D17 -> 4880 | E34: mm
B35: Shell Inside Dia. | C35: D_s | D35: =INPUTS!D49 -> 500 | E35: mm
B36: Total Heat Transfer Area | C36: A_HT | D36: =INPUTS!D45*PI()*INPUTS!D13/1000*INPUTS!D17/1000 -> 116.82201 | E36: m²
B38: DISCLAIMER: This spreadsheet is a calculation aid. Results shall be verified by a qualified engineer against the applicable edition of ASME VIII, TEMA, API 660 and IOGP S-614. The engineer of record is responsible for all design decisions.
